Workbook

Sheet DD
B1: Công ty: CÔNG TY
B2: Địa chỉ:
B3: BẢNG CHI TIẾT CHẤM CÔNG
B4: Mã nhân viên: 00042 Tên nhân viên: Anh Thư Phòng ban: ---
B5: Tổng giờ | D5: 18.22 | G5: Số lần trễ | I5: 4 | K5: Số phút trễ | M5: 241
B6: Tổng công | D6: 1.81 | G6: Số lần sớm | I6: 4 | K6: Số phút sớm | M6: 1066
B7: Tăng ca | D7: 0 | E7: 0 | G7: Vắng KP | I7: 12 | K7: Vắng CP | M7: 0
B8: Chi tiết
B9: Ngày | C9: Thứ | D9: 1 | F9: 2 | H9: 3 | J9: Trễ | K9: Sớm | L9: Về trễ | M9: Giờ | N9: Công | O9: T.Ca1 | P9: T.Ca2 | Q9: T.Ca3 | R9: T.Ca4 | S9: Ký hiệu | T9: Tổng công
D10: Vào | E10: Ra | F10: Vào | G10: Ra | H10: Vào | I10: Ra
B11: 24/02/2026 | C11: Ba | D11: 12:48 | E11: 18:54 | J11: 0 | K11: 0 | L11: 0 | M11: 0 | N11: 0 | O11: 0 | P11: 0 | Q11: 0 | R11: 0 | S11: V | T11: 1
B12: 25/02/2026 | C12: Tư | J12: 0 | K12: 0 | L12: 0 | M12: 0 | N12: 0 | O12: 0 | P12: 0 | Q12: 0 | R12: 0 | S12: V
B13: 26/02/2026 | C13: Năm | D13: 12:50 | E13: 18:25 | J13: 0 | K13: 0 | L13: 0 | M13: 0 | N13: 0 | O13: 0 | P13: 0 | Q13: 0 | R13: 0 | S13: V | T13: 1
B14: 27/02/2026 | C14: Sáu | D14: 07:58 | E14: 18:26 | J14: 0 | K14: 0 | L14: 0 | M14: 0 | N14: 0 | O14: 0 | P14: 0 | Q14: 0 | R14: 0 | S14: V | T14: 2
B15: 28/02/2026 | C15: Bảy | J15: 0 | K15: 0 | L15: 0 | M15: 0 | N15: 0 | O15: 0 | P15: 0 | Q15: 0 | R15: 0 | S15: V
B16: 01/03/2026 | C16: CN | D16: 07:58 | E16: 18:06 | J16: 0 | K16: 0 | L16: 0 | M16: 0 | N16: 0 | O16: 0 | P16: 0 | Q16: 0 | R16: 0 | S16: V | T16: 2
B17: 02/03/2026 | C17: Hai | J17: 0 | K17: 0 | L17: 0 | M17: 0 | N17: 0 | O17: 0 | P17: 0 | Q17: 0 | R17: 0 | S17: V
B18: 03/03/2026 | C18: Ba | J18: 0 | K18: 0 | L18: 0 | M18: 0 | N18: 0 | O18: 0 | P18: 0 | Q18: 0 | R18: 0 | S18: V
B19: 04/03/2026 | C19: Tư | J19: 0 | K19: 0 | L19: 0 | M19: 0 | N19: 0 | O19: 0 | P19: 0 | Q19: 0 | R19: 0 | S19: V
A20: Phạt trễ 8*3=24k | B20: 05/03/2026 | C20: Năm | D20: 17:11 | E20: 21:59 | F20: -11 | J20: 0 | K20: 0 | L20: 0 | M20: 0 | N20: 0 | O20: 0 | P20: 0 | Q20: 0 | R20: 0 | S20: V | T20: 1
B21: 06/03/2026 | C21: Sáu | D21: 08:02 | E21: 12:35 | F21: -27 | J21: 62 | K21: 265 | L21: 0 | M21: 4.55 | N21: 0.45 | O21: 0 | P21: 0 | Q21: 0 | R21: 0 | S21: X | T21: 1
B22: 07/03/2026 | C22: Bảy | J22: 0 | K22: 0 | L22: 0 | M22: 0 | N22: 0 | O22: 0 | P22: 0 | Q22: 0 | R22: 0 | S22: V
B23: 08/03/2026 | C23: CN | J23: 0 | K23: 0 | L23: 0 | M23: 0 | N23: 0 | O23: 0 | P23: 0 | Q23: 0 | R23: 0 | S23: V
A24: Phạt trễ 6*3=18k | B24: 09/03/2026 | C24: Hai | D24: 17:09 | E24: 21:59 | F24: -9 | J24: 0 | K24: 0 | L24: 0 | M24: 0 | N24: 0 | O24: 0 | P24: 0 | Q24: 0 | R24: 0 | S24: V | T24: 1
B25: 10/03/2026 | C25: Ba | D25: 08:01 | E25: 12:33 | F25: -28 | J25: 61 | K25: 266 | L25: 0 | M25: 4.55 | N25: 0.45 | O25: 0 | P25: 0 | Q25: 0 | R25: 0 | S25: X | T25: 1
B26: 11/03/2026 | C26: Tư | J26: 0 | K26: 0 | L26: 0 | M26: 0 | N26: 0 | O26: 0 | P26: 0 | Q26: 0 | R26: 0 | S26: V
B27: 12/03/2026 | C27: Năm | D27: 08:00 | E27: 12:33 | F27: -27 | J27: 60 | K27: 266 | L27: 0 | M27: 4.57 | N27: 0.46 | O27: 0 | P27: 0 | Q27: 0 | R27: 0 | S27: X | T27: 1
A28: Phạt trễ 6*3=18k | B28: 13/03/2026 | C28: Sáu | D28: 17:09 | E28: 22:04 | F28: -9 | J28: 0 | K28: 0 | L28: 0 | M28: 0 | N28: 0 | O28: 0 | P28: 0 | Q28: 0 | R28: 0 | S28: V | T28: 1
B29: 14/03/2026 | C29: Bảy | J29: 0 | K29: 0 | L29: 0 | M29: 0 | N29: 0 | O29: 0 | P29: 0 | Q29: 0 | R29: 0 | S29: V
B30: 15/03/2026 | C30: CN | D30: 12:53 | E30: 22:01 | J30: 0 | K30: 0 | L30: 0 | M30: 0 | N30: 0 | O30: 0 | P30: 0 | Q30: 0 | R30: 0 | S30: V | T30: 2
A31: XT | B31: 16/03/2026 | C31: Hai | D31: 17:14 | E31: 21:59 | F31: -14 | J31: 0 | K31: 0 | L31: 0 | M31: 0 | N31: 0 | O31: 0 | P31: 0 | Q31: 0 | R31: 0 | S31: V | T31: 1
B32: 17/03/2026 | C32: Ba | J32: 0 | K32: 0 | L32: 0 | M32: 0 | N32: 0 | O32: 0 | P32: 0 | Q32: 0 | R32: 0 | S32: V
B33: 18/03/2026 | C33: Tư | J33: 0 | K33: 0 | L33: 0 | M33: 0 | N33: 0 | O33: 0 | P33: 0 | Q33: 0 | R33: 0 | S33: V
B34: 19/03/2026 | C34: Năm | J34: 0 | K34: 0 | L34: 0 | M34: 0 | N34: 0 | O34: 0 | P34: 0 | Q34: 0 | R34: 0 | S34: V
B35: 20/03/2026 | C35: Sáu | D35: 07:58 | E35: 12:30 | F35: -30 | J35: 58 | K35: 269 | L35: 0 | M35: 4.55 | N35: 0.45 | O35: 0 | P35: 0 | Q35: 0 | R35: 0 | S35: X | T35: 1
B36: 21/03/2026 | C36: Bảy | J36: 0 | K36: 0 | L36: 0 | M36: 0 | N36: 0 | O36: 0 | P36: 0 | Q36: 0 | R36: 0 | S36: V
B37: 22/03/2026 | C37: CN | D37: 07:57 | E37: 18:00 | J37: 0 | K37: 0 | L37: 0 | M37: 0 | N37: 0 | O37: 0 | P37: 0 | Q37: 0 | R37: 0 | S37: V | T37: 2
A38: Phạt trễ 4*3=12k | B38: 23/03/2026 | C38: Hai | D38: 17:07 | J38: 0 | K38: 0 | L38: 0 | M38: 0 | N38: 0 | O38: 0 | P38: 0 | Q38: 0 | R38: 0 | S38: O | T38: 1
F39: =SUM(F11:F38) -> -155 | T39: =SUM(T11:T38) -> 19
B41: =110000/5/60 -> 366.66667
...

Sheet HV
B1: BẢNG CHI TIẾT CHẤM CÔNG
B2: Mã nhân viên: NV7 Tên nhân viên: anh thư Bộ phận: BÁN HÀNG
B3: Công làm | E3: Làm thêm | I3: Đi muộn | M3: Về sớm
B4: Tổng giờ | C4: 5 | E4: Số phút | G4: 5 | I4: Số phút | K4: 0 | M4: Số phút | O4: 0
B5: Số công | C5: 1 | I5: Số lần | K5: 0 | M5: Số lần | O5: 0
B6: Chi tiết
B7: Ngày | C7: Thứ | D7: Ca | E7: TG Vào Ra | G7: Muộn | H7: Sớm | I7: T.Giờ | J7: Công | K7: L.Thêm | L7: Ghi chú | Q7: Tổng ca
E8: Đầu | F8: Cuối
B9: 46077 | C9: T3 | G9: 0 | H9: 0 | I9: 0 | J9: 0 | K9: 0
B10: 46078 | C10: T4 | G10: 0 | H10: 0 | I10: 0 | J10: 0 | K10: 0
B11: 46079 | C11: T5 | G11: 0 | H11: 0 | I11: 0 | J11: 0 | K11: 0
B12: 46080 | C12: T6 | G12: 0 | H12: 0 | I12: 0 | J12: 0 | K12: 0
B13: 46081 | C13: T7 | G13: 0 | H13: 0 | I13: 0 | J13: 0 | K13: 0
B14: 46082 | C14: CN | G14: 0 | H14: 0 | I14: 0 | J14: 0 | K14: 0
B15: 46083 | C15: T2 | G15: 0 | H15: 0 | I15: 0 | J15: 0 | K15: 0
B16: 46084 | C16: T3 | G16: 0 | H16: 0 | I16: 0 | J16: 0 | K16: 0
B17: 46085 | C17: T4 | G17: 0 | H17: 0 | I17: 0 | J17: 0 | K17: 0
B18: 46086 | C18: T5 | G18: 0 | H18: 0 | I18: 0 | J18: 0 | K18: 0
B19: 46087 | C19: T6 | G19: 0 | H19: 0 | I19: 0 | J19: 0 | K19: 0
A20: Thưởng lễ 50k | B20: 46088 | C20: T7 | D20: CA2 | E20: 46088.54 | F20: 46088.753 | G20: 0 | H20: 0 | I20: 8 | J20: 1 | K20: 5 | Q20: 1
B21: 46089 | C21: CN | G21: 0 | H21: 0 | I21: 0 | J21: 0 | K21: 0
B22: 46090 | C22: T2 | G22: 0 | H22: 0 | I22: 0 | J22: 0 | K22: 0
B23: 46091 | C23: T3 | G23: 0 | H23: 0 | I23: 0 | J23: 0 | K23: 0
B24: 46092 | C24: T4 | G24: 0 | H24: 0 | I24: 0 | J24: 0 | K24: 0
B25: 46093 | C25: T5 | G25: 0 | H25: 0 | I25: 0 | J25: 0 | K25: 0
B26: 46094 | C26: T6 | G26: 0 | H26: 0 | I26: 0 | J26: 0 | K26: 0
B27: 46095 | C27: T7 | G27: 0 | H27: 0 | I27: 0 | J27: 0 | K27: 0
B28: 46096 | C28: CN | G28: 0 | H28: 0 | I28: 0 | J28: 0 | K28: 0
B29: 46097 | C29: T2 | G29: 0 | H29: 0 | I29: 0 | J29: 0 | K29: 0
B30: 46098 | C30: T3 | G30: 0 | H30: 0 | I30: 0 | J30: 0 | K30: 0
B31: 46099 | C31: T4 | G31: 0 | H31: 0 | I31: 0 | J31: 0 | K31: 0
B32: 46100 | C32: T5 | G32: 0 | H32: 0 | I32: 0 | J32: 0 | K32: 0
... B36: 46104 | C36: T2 | G36: 0 | H36: 0 | I36: 0 | J36: 0 | K36: 0

Sheet NT
B1: Công ty: CÔNG TY
B2: Địa chỉ:
B3: BẢNG CHI TIẾT CHẤM CÔNG
B4: Mã nhân viên: 00023 Tên nhân viên: Anh Thư Phòng ban: ---
B5: Tổng giờ | D5: 19.03 | G5: Số lần trễ | I5: 2 | K5: Số phút trễ | M5: 34
B6: Tổng công | D6: 3.81 | G6: Số lần sớm | I6: 1 | K6: Số phút sớm | M6: 24
B7: Tăng ca | D7: 0.09 | E7: 0 | G7: Vắng KP | I7: 24 | K7: Vắng CP | M7: 0
B8: Chi tiết
B9: Ngày | C9: Thứ | D9: 1 | F9: 2 | H9: 3 | J9: Trễ | K9: Sớm | L9: Về trễ | M9: Giờ | N9: Công | O9: T.Ca1 | P9: T.Ca2 | Q9: T.Ca3 | R9: T.Ca4 | S9: Ký hiệu | T9: Tổng ca
D10: Vào | E10: Ra | F10: Vào | G10: Ra | H10: Vào | I10: Ra
B11: 2/17/2026 | C11: Ba | J11: 0 | K11: 0 | L11: 0 | M11: 0 | N11: 0 | O11: 0 | P11: 0 | Q11: 0 | R11: 0 | S11: V
B12: 2/18/2026 | C12: Tư | J12: 0 | K12: 0 | L12: 0 | M12: 0 | N12: 0 | O12: 0 | P12: 0 | Q12: 0 | R12: 0 | S12: V
B13: 2/19/2026 | C13: Năm | J13: 0 | K13: 0 | L13: 0 | M13: 0 | N13: 0 | O13: 0 | P13: 0 | Q13: 0 | R13: 0 | S13: V
B14: 2/20/2026 | C14: Sáu | J14: 0 | K14: 0 | L14: 0 | M14: 0 | N14: 0 | O14: 0 | P14: 0 | Q14: 0 | R14: 0 | S14: V
B15: 2/21/2026 | C15: Bảy | J15: 0 | K15: 0 | L15: 0 | M15: 0 | N15: 0 | O15: 0 | P15: 0 | Q15: 0 | R15: 0 | S15: V
B16: 2/22/2026 | C16: CN | J16: 0 | K16: 0 | L16: 0 | M16: 0 | N16: 0 | O16: 0 | P16: 0 | Q16: 0 | R16: 0 | S16: V
B17: 2/23/2026 | C17: Hai | J17: 0 | K17: 0 | L17: 0 | M17: 0 | N17: 0 | O17: 0 | P17: 0 | Q17: 0 | R17: 0 | S17: V
B18: 2/24/2026 | C18: Ba | J18: 0 | K18: 0 | L18: 0 | M18: 0 | N18: 0 | O18: 0 | P18: 0 | Q18: 0 | R18: 0 | S18: V
B19: 2/25/2026 | C19: Tư | J19: 0 | K19: 0 | L19: 0 | M19: 0 | N19: 0 | O19: 0 | P19: 0 | Q19: 0 | R19: 0 | S19: V
B20: 2/26/2026 | C20: Năm | J20: 0 | K20: 0 | L20: 0 | M20: 0 | N20: 0 | O20: 0 | P20: 0 | Q20: 0 | R20: 0 | S20: V
B21: 2/27/2026 | C21: Sáu | J21: 0 | K21: 0 | L21: 0 | M21: 0 | N21: 0 | O21: 0 | P21: 0 | Q21: 0 | R21: 0 | S21: V
B22: 2/28/2026 | C22: Bảy | D22: 12:53 | E22: 19:32 | J22: 0 | K22: 0 | L22: 0 | M22: 0 | N22: 0 | O22: 0 | P22: 0 | Q22: 0 | R22: 0 | S22: V | T22: 1
B23: 3/1/2026 | C23: CN | J23: 0 | K23: 0 | L23: 0 | M23: 0 | N23: 0 | O23: 0 | P23: 0 | Q23: 0 | R23: 0 | S23: V
B24: 3/2/2026 | C24: Hai | J24: 0 | K24: 0 | L24: 0 | M24: 0 | N24: 0 | O24: 0 | P24: 0 | Q24: 0 | R24: 0 | S24: V
B25: 3/3/2026 | C25: Ba | J25: 0 | K25: 0 | L25: 0 | M25: 0 | N25: 0 | O25: 0 | P25: 0 | Q25: 0 | R25: 0 | S25: V
B26: 3/4/2026 | C26: Tư | D26: 16:39 | E26: 22:01 | J26: 0 | K26: 0 | L26: 1 | M26: 5 | N26: 1 | O26: 0.02 | P26: 0 | Q26: 0 | R26: 0 | S26: X | T26: 1
B27: 3/5/2026 | C27: Năm | J27: 0 | K27: 0 | L27: 0 | M27: 0 | N27: 0 | O27: 0 | P27: 0 | Q27: 0 | R27: 0 | S27: V
B28: 3/6/2026 | C28: Sáu | J28: 0 | K28: 0 | L28: 0 | M28: 0 | N28: 0 | O28: 0 | P28: 0 | Q28: 0 | R28: 0 | S28: V
B29: 3/7/2026 | C29: Bảy | J29: 0 | K29: 0 | L29: 0 | M29: 0 | N29: 0 | O29: 0 | P29: 0 | Q29: 0 | R29: 0 | S29: V
A30: Thưởng lễ 100k | B30: 3/8/2026 | C30: CN | D30: 0.29444444 | E30: 18:45 | F30: =56+45 -> 101 | J30: 0 | K30: 0 | L30: 0 | M30: 0 | N30: 0 | O30: 0 | P30: 0 | Q30: 0 | R30: 0 | S30: V | T30: 2
B31: 3/9/2026 | C31: Hai | J31: 0 | K31: 0 | L31: 0 | M31: 0 | N31: 0 | O31: 0 | P31: 0 | Q31: 0 | R31: 0 | S31: V
B32: 3/10/2026 | C32: Ba | J32: 0 | K32: 0 | L32: 0 | M32: 0 | N32: 0 | O32: 0 | P32: 0 | Q32: 0 | R32: 0 | S32: V
B33: 3/11/2026 | C33: Tư | J33: 0 | K33: 0 | L33: 0 | M33: 0 | N33: 0 | O33: 0 | P33: 0 | Q33: 0 | R33: 0 | S33: V
B34: 3/12/2026 | C34: Năm | J34: 0 | K34: 0 | L34: 0 | M34: 0 | N34: 0 | O34: 0 | P34: 0 | Q34: 0 | R34: 0 | S34: V
B35: 3/13/2026 | C35: Sáu | J35: 0 | K35: 0 | L35: 0 | M35: 0 | N35: 0 | O35: 0 | P35: 0 | Q35: 0 | R35: 0 | S35: V
B36: 3/14/2026 | C36: Bảy | D36: 12:57 | E36: 18:01 | J36: 0 | K36: 0 | L36: 1 | M36: 5 | N36: 1 | O36: 0.02 | P36: 0 | Q36: 0 | R36: 0 | S36: X | T36: 1
B37: 3/15/2026 | C37: CN | J37: 0 | K37: 0 | L37: 0 | M37: 0 | N37: 0 | O37: 0 | P37: 0 | Q37: 0 | R37: 0 | S37: V
B38: 3/16/2026 | C38: Hai | J38: 0 | K38: 0 | L38: 0 | M38: 0 | N38: 0 | O38: 0 | P38: 0 | Q38: 0 | R38: 0 | S38: V
A39: Phạt trễ 19*3=57k | B39: 3/17/2026 | C39: Ba | D39: 17:22 | E39: 22:03 | J39: 22 | K39: 0 | L39: 3 | M39: 4.63 | N39: 0.93 | O39: 0.05 | P39: 0 | Q39: 0 | R39: 0 | S39: X | T39: 1
B40: 3/18/2026 | C40: Tư | J40: 0 | K40: 0 | L40: 0 | M40: 0 | N40: 0 | O40: 0 | P40: 0 | Q40: 0 | R40: 0 | S40: V
...
